<?xml version="1.0" ?>
<robot name="exocet_mm40_main" xmlns:xacro="http://www.ros.org/wiki/xacro">

<xacro:include filename="$(find exocet_mm40_main_description)/urdf/materials.xacro" />
<xacro:include filename="$(find exocet_mm40_main_description)/urdf/exocet_mm40_main.trans" />
<xacro:include filename="$(find exocet_mm40_main_description)/urdf/exocet_mm40_main.gazebo" />
<link name="base_link">
  <inertial>
    <origin xyz="1.4687012896574618e-07 -2.0321629593085347e-07 -2.3064131171409382e-07" rpy="0 0 0"/>
    <mass value="3649.219349319701"/>
    <inertia ixx="62.482615" iyy="6080.100511" izz="6080.100589" ixy="-1.574131" iyz="-0.005624" ixz="-1.570299"/>
  </inertial>
  <visual>
    <origin xyz="0 0 0" rpy="0 0 0"/>
    <geometry>
      <mesh filename="package://exocet_mm40_main_description/meshes/base_link.stl" scale="0.001 0.001 0.001"/>
    </geometry>
    <material name="silver"/>
  </visual>
  <collision>
    <origin xyz="0 0 0" rpy="0 0 0"/>
    <geometry>
      <mesh filename="package://exocet_mm40_main_description/meshes/base_link.stl" scale="0.001 0.001 0.001"/>
    </geometry>
  </collision>
</link>

<link name="wing_1">
  <inertial>
    <origin xyz="0.029454289507047537 1.6278506031726717e-07 0.11144906411972477" rpy="0 0 0"/>
    <mass value="27.520144470345386"/>
    <inertia ixx="0.139887" iyy="0.954585" izz="0.818182" ixy="-0.0" iyz="-0.0" ixz="0.056191"/>
  </inertial>
  <visual>
    <origin xyz="0.790271 0.001244 -0.24488" rpy="0 0 0"/>
    <geometry>
      <mesh filename="package://exocet_mm40_main_description/meshes/wing_1.stl" scale="0.001 0.001 0.001"/>
    </geometry>
    <material name="silver"/>
  </visual>
  <collision>
    <origin xyz="0.790271 0.001244 -0.24488" rpy="0 0 0"/>
    <geometry>
      <mesh filename="package://exocet_mm40_main_description/meshes/wing_1.stl" scale="0.001 0.001 0.001"/>
    </geometry>
  </collision>
</link>

<link name="wing_2">
  <inertial>
    <origin xyz="0.029454289507047537 -0.1114496590324433 1.195027642391256e-07" rpy="0 0 0"/>
    <mass value="27.520144470345386"/>
    <inertia ixx="0.139887" iyy="0.818182" izz="0.954585" ixy="-0.056191" iyz="0.0" ixz="-0.0"/>
  </inertial>
  <visual>
    <origin xyz="0.790271 0.247367 0.001244" rpy="0 0 0"/>
    <geometry>
      <mesh filename="package://exocet_mm40_main_description/meshes/wing_2.stl" scale="0.001 0.001 0.001"/>
    </geometry>
    <material name="silver"/>
  </visual>
  <collision>
    <origin xyz="0.790271 0.247367 0.001244" rpy="0 0 0"/>
    <geometry>
      <mesh filename="package://exocet_mm40_main_description/meshes/wing_2.stl" scale="0.001 0.001 0.001"/>
    </geometry>
  </collision>
</link>

<link name="wing_3">
  <inertial>
    <origin xyz="0.029454289507047537 0.11144931324957774 2.254434818024613e-07" rpy="0 0 0"/>
    <mass value="27.520144470345386"/>
    <inertia ixx="0.139887" iyy="0.818182" izz="0.954585" ixy="0.056191" iyz="0.0" ixz="0.0"/>
  </inertial>
  <visual>
    <origin xyz="0.790271 -0.24488 0.001244" rpy="0 0 0"/>
    <geometry>
      <mesh filename="package://exocet_mm40_main_description/meshes/wing_3.stl" scale="0.001 0.001 0.001"/>
    </geometry>
    <material name="silver"/>
  </visual>
  <collision>
    <origin xyz="0.790271 -0.24488 0.001244" rpy="0 0 0"/>
    <geometry>
      <mesh filename="package://exocet_mm40_main_description/meshes/wing_3.stl" scale="0.001 0.001 0.001"/>
    </geometry>
  </collision>
</link>

<link name="wing_4">
  <inertial>
    <origin xyz="0.029454289507047537 2.754692736113909e-07 -0.1114498946753047" rpy="0 0 0"/>
    <mass value="27.520144470345386"/>
    <inertia ixx="0.139887" iyy="0.954585" izz="0.818182" ixy="0.0" iyz="-0.0" ixz="-0.056191"/>
  </inertial>
  <visual>
    <origin xyz="0.790271 0.001244 0.247367" rpy="0 0 0"/>
    <geometry>
      <mesh filename="package://exocet_mm40_main_description/meshes/wing_4.stl" scale="0.001 0.001 0.001"/>
    </geometry>
    <material name="silver"/>
  </visual>
  <collision>
    <origin xyz="0.790271 0.001244 0.247367" rpy="0 0 0"/>
    <geometry>
      <mesh filename="package://exocet_mm40_main_description/meshes/wing_4.stl" scale="0.001 0.001 0.001"/>
    </geometry>
  </collision>
</link>

<link name="fin_holder_1">
  <inertial>
    <origin xyz="0.00046631535121388623 8.551026908494401e-08 0.019397083693300482" rpy="0 0 0"/>
    <mass value="1.2214564912863308"/>
    <inertia ixx="0.000289" iyy="0.007807" izz="0.007576" ixy="-0.0" iyz="0.0" ixz="0.000163"/>
  </inertial>
  <visual>
    <origin xyz="2.047364 0.001244 -0.198823" rpy="0 0 0"/>
    <geometry>
      <mesh filename="package://exocet_mm40_main_description/meshes/fin_holder_1.stl" scale="0.001 0.001 0.001"/>
    </geometry>
    <material name="silver"/>
  </visual>
  <collision>
    <origin xyz="2.047364 0.001244 -0.198823" rpy="0 0 0"/>
    <geometry>
      <mesh filename="package://exocet_mm40_main_description/meshes/fin_holder_1.stl" scale="0.001 0.001 0.001"/>
    </geometry>
  </collision>
</link>

<link name="fin_holder_2">
  <inertial>
    <origin xyz="0.00046654244509625187 -0.01939766646183036 1.2048149441936003e-07" rpy="0 0 0"/>
    <mass value="1.2214564912863308"/>
    <inertia ixx="0.000289" iyy="0.007576" izz="0.007807" ixy="-0.000163" iyz="-0.0" ixz="-0.0"/>
  </inertial>
  <visual>
    <origin xyz="2.047364 0.2014 0.001244" rpy="0 0 0"/>
    <geometry>
      <mesh filename="package://exocet_mm40_main_description/meshes/fin_holder_2.stl" scale="0.001 0.001 0.001"/>
    </geometry>
    <material name="silver"/>
  </visual>
  <collision>
    <origin xyz="2.047364 0.2014 0.001244" rpy="0 0 0"/>
    <geometry>
      <mesh filename="package://exocet_mm40_main_description/meshes/fin_holder_2.stl" scale="0.001 0.001 0.001"/>
    </geometry>
  </collision>
</link>

<link name="fin_holder_3">
  <inertial>
    <origin xyz="0.0004657644542707118 0.019397167023261913 3.124515561993453e-06" rpy="0 0 0"/>
    <mass value="1.2214564912863308"/>
    <inertia ixx="0.000289" iyy="0.007576" izz="0.007807" ixy="0.000163" iyz="-0.0" ixz="0.0"/>
  </inertial>
  <visual>
    <origin xyz="2.047364 -0.198913 0.001244" rpy="0 0 0"/>
    <geometry>
      <mesh filename="package://exocet_mm40_main_description/meshes/fin_holder_3.stl" scale="0.001 0.001 0.001"/>
    </geometry>
    <material name="silver"/>
  </visual>
  <collision>
    <origin xyz="2.047364 -0.198913 0.001244" rpy="0 0 0"/>
    <geometry>
      <mesh filename="package://exocet_mm40_main_description/meshes/fin_holder_3.stl" scale="0.001 0.001 0.001"/>
    </geometry>
  </collision>
</link>

<link name="fin_holder_4">
  <inertial>
    <origin xyz="0.00046576445427159996 3.1609702282331398e-06 -0.019397755197605754" rpy="0 0 0"/>
    <mass value="1.2214564912863308"/>
    <inertia ixx="0.000289" iyy="0.007807" izz="0.007576" ixy="0.0" iyz="0.0" ixz="-0.000163"/>
  </inertial>
  <visual>
    <origin xyz="2.047364 0.001244 0.2014" rpy="0 0 0"/>
    <geometry>
      <mesh filename="package://exocet_mm40_main_description/meshes/fin_holder_4.stl" scale="0.001 0.001 0.001"/>
    </geometry>
    <material name="silver"/>
  </visual>
  <collision>
    <origin xyz="2.047364 0.001244 0.2014" rpy="0 0 0"/>
    <geometry>
      <mesh filename="package://exocet_mm40_main_description/meshes/fin_holder_4.stl" scale="0.001 0.001 0.001"/>
    </geometry>
  </collision>
</link>

<link name="fin_1">
  <inertial>
    <origin xyz="-0.021990822219934092 -2.6700898126698607e-06 0.06917037549605992" rpy="0 0 0"/>
    <mass value="2.933547797664029"/>
    <inertia ixx="0.008743" iyy="0.016181" izz="0.00753" ixy="-0.0" iyz="0.0" ixz="0.00278"/>
  </inertial>
  <visual>
    <origin xyz="2.049158 0.001247 -0.235271" rpy="0 0 0"/>
    <geometry>
      <mesh filename="package://exocet_mm40_main_description/meshes/fin_1.stl" scale="0.001 0.001 0.001"/>
    </geometry>
    <material name="silver"/>
  </visual>
  <collision>
    <origin xyz="2.049158 0.001247 -0.235271" rpy="0 0 0"/>
    <geometry>
      <mesh filename="package://exocet_mm40_main_description/meshes/fin_1.stl" scale="0.001 0.001 0.001"/>
    </geometry>
  </collision>
</link>

<link name="fin_2">
  <inertial>
    <origin xyz="-0.021990596607152302 -0.06917123913887535 -2.1522670956991303e-06" rpy="0 0 0"/>
    <mass value="2.933547797664029"/>
    <inertia ixx="0.008743" iyy="0.00753" izz="0.016181" ixy="-0.00278" iyz="-0.0" ixz="-0.0"/>
  </inertial>
  <visual>
    <origin xyz="2.049157 0.237848 0.001247" rpy="0 0 0"/>
    <geometry>
      <mesh filename="package://exocet_mm40_main_description/meshes/fin_2.stl" scale="0.001 0.001 0.001"/>
    </geometry>
    <material name="silver"/>
  </visual>
  <collision>
    <origin xyz="2.049157 0.237848 0.001247" rpy="0 0 0"/>
    <geometry>
      <mesh filename="package://exocet_mm40_main_description/meshes/fin_2.stl" scale="0.001 0.001 0.001"/>
    </geometry>
  </collision>
</link>

<link name="fin_3">
  <inertial>
    <origin xyz="-0.02199283450896594 0.06916976475605402 1.230936505195574e-05" rpy="0 0 0"/>
    <mass value="2.933547797664029"/>
    <inertia ixx="0.008743" iyy="0.00753" izz="0.016181" ixy="0.00278" iyz="-2e-06" ixz="1e-06"/>
  </inertial>
  <visual>
    <origin xyz="2.049159 -0.235361 0.001235" rpy="0 0 0"/>
    <geometry>
      <mesh filename="package://exocet_mm40_main_description/meshes/fin_3.stl" scale="0.001 0.001 0.001"/>
    </geometry>
    <material name="silver"/>
  </visual>
  <collision>
    <origin xyz="2.049159 -0.235361 0.001235" rpy="0 0 0"/>
    <geometry>
      <mesh filename="package://exocet_mm40_main_description/meshes/fin_3.stl" scale="0.001 0.001 0.001"/>
    </geometry>
  </collision>
</link>

<link name="fin_4">
  <inertial>
    <origin xyz="-0.021992834508965498 1.219549679630635e-05 -0.06917035296197155" rpy="0 0 0"/>
    <mass value="2.933547797664029"/>
    <inertia ixx="0.008743" iyy="0.016181" izz="0.00753" ixy="0.0" iyz="2e-06" ixz="-0.00278"/>
  </inertial>
  <visual>
    <origin xyz="2.049159 0.001235 0.237848" rpy="0 0 0"/>
    <geometry>
      <mesh filename="package://exocet_mm40_main_description/meshes/fin_4.stl" scale="0.001 0.001 0.001"/>
    </geometry>
    <material name="silver"/>
  </visual>
  <collision>
    <origin xyz="2.049159 0.001235 0.237848" rpy="0 0 0"/>
    <geometry>
      <mesh filename="package://exocet_mm40_main_description/meshes/fin_4.stl" scale="0.001 0.001 0.001"/>
    </geometry>
  </collision>
</link>

<joint name="Wing1_Ref" type="revolute">
  <origin xyz="-0.790271 -0.001244 0.24488" rpy="0 0 0"/>
  <parent link="base_link"/>
  <child link="wing_1"/>
  <axis xyz="1.0 0.0 0.0"/>
  <limit upper="2.094395" lower="-2.094395" effort="100" velocity="100"/>
</joint>

<joint name="Wing2_Rev" type="revolute">
  <origin xyz="-0.790271 -0.247367 -0.001244" rpy="0 0 0"/>
  <parent link="base_link"/>
  <child link="wing_2"/>
  <axis xyz="1.0 0.0 0.0"/>
  <limit upper="2.094395" lower="-2.094395" effort="100" velocity="100"/>
</joint>

<joint name="Wing3_Rev" type="revolute">
  <origin xyz="-0.790271 0.24488 -0.001244" rpy="0 0 0"/>
  <parent link="base_link"/>
  <child link="wing_3"/>
  <axis xyz="1.0 0.0 0.0"/>
  <limit upper="2.094395" lower="-2.094395" effort="100" velocity="100"/>
</joint>

<joint name="Wing4_Rev" type="revolute">
  <origin xyz="-0.790271 -0.001244 -0.247367" rpy="0 0 0"/>
  <parent link="base_link"/>
  <child link="wing_4"/>
  <axis xyz="1.0 0.0 0.0"/>
  <limit upper="2.094395" lower="-2.094395" effort="100" velocity="100"/>
</joint>

<joint name="FinHold1_Rev" type="revolute">
  <origin xyz="-2.047364 -0.001244 0.198823" rpy="0 0 0"/>
  <parent link="base_link"/>
  <child link="fin_holder_1"/>
  <axis xyz="2.9e-05 -3.7e-05 1.0"/>
  <limit upper="0.349066" lower="-0.349066" effort="100" velocity="100"/>
</joint>

<joint name="FinHold2_Rev" type="revolute">
  <origin xyz="-2.047364 -0.2014 -0.001244" rpy="0 0 0"/>
  <parent link="base_link"/>
  <child link="fin_holder_2"/>
  <axis xyz="4e-05 -1.0 -3.2e-05"/>
  <limit upper="0.349066" lower="-0.349066" effort="100" velocity="100"/>
</joint>

<joint name="FinHold3_Rev" type="revolute">
  <origin xyz="-2.047364 0.198913 -0.001244" rpy="0 0 0"/>
  <parent link="base_link"/>
  <child link="fin_holder_3"/>
  <axis xyz="0.0 1.0 0.000181"/>
  <limit upper="0.349066" lower="-0.349066" effort="100" velocity="100"/>
</joint>

<joint name="FinHold4_Rev" type="revolute">
  <origin xyz="-2.047364 -0.001244 -0.2014" rpy="0 0 0"/>
  <parent link="base_link"/>
  <child link="fin_holder_4"/>
  <axis xyz="0.0 0.00018 -1.0"/>
  <limit upper="0.349066" lower="-0.349066" effort="100" velocity="100"/>
</joint>

<joint name="Fin1_Rev" type="revolute">
  <origin xyz="-0.001794 -3e-06 0.036448" rpy="0 0 0"/>
  <parent link="fin_holder_1"/>
  <child link="fin_1"/>
  <axis xyz="-1.0 -0.0 2.9e-05"/>
  <limit upper="2.094395" lower="-2.094395" effort="100" velocity="100"/>
</joint>

<joint name="Fin2_Rev" type="revolute">
  <origin xyz="-0.001793 -0.036448 -3e-06" rpy="0 0 0"/>
  <parent link="fin_holder_2"/>
  <child link="fin_2"/>
  <axis xyz="-1.0 -4e-05 -0.0"/>
  <limit upper="2.094395" lower="-2.094395" effort="100" velocity="100"/>
</joint>

<joint name="Fin3_Rev" type="revolute">
  <origin xyz="-0.001795 0.036448 9e-06" rpy="0 0 0"/>
  <parent link="fin_holder_3"/>
  <child link="fin_3"/>
  <axis xyz="-1.0 0.0 0.0"/>
  <limit upper="2.094395" lower="-2.094395" effort="100" velocity="100"/>
</joint>

<joint name="Fin4_Rev" type="revolute">
  <origin xyz="-0.001795 9e-06 -0.036448" rpy="0 0 0"/>
  <parent link="fin_holder_4"/>
  <child link="fin_4"/>
  <axis xyz="-1.0 -0.0 0.0"/>
  <limit upper="2.094395" lower="-2.094395" effort="100" velocity="100"/>
</joint>

</robot>
